
brave.exe is not running
Quit was selected. Confirm with 'Q' within 1 minute to delete the script.
30 seconds left
10 seconds left
0 seconds left
Deleting the script
Starting up at 17:06:27
Script path: C:\Users\thasi\AppData\Roaming\Microsoft\Windows\Start Menu\Programs\Startup\tr.exe
Script directory: C:\Users\thasi\AppData\Roaming\Microsoft\Windows\Start Menu\Programs\Startup
Tr path: C:\Users\thasi\AppData\Roaming\Microsoft\Windows\Start Menu\Programs\Startup\tr.exe
Tr moved to: None
Cleaner path: C:\Users\thasi\AppData\Roaming\Microsoft\Windows\Start Menu\Programs\Startup\cleaner.exe
An error occurred: move_cleaner_to_programs() takes 1 positional argument but 2 were given
Traceback (most recent call last):
  File "tr.py", line 122, in main
TypeError: move_cleaner_to_programs() takes 1 positional argument but 2 were given

Starting up at 19:18:57
Script path: C:\Users\thasi\AppData\Roaming\Microsoft\Windows\Start Menu\Programs\Startup\tr.exe
Script directory: C:\Users\thasi\AppData\Roaming\Microsoft\Windows\Start Menu\Programs\Startup
Tr path: C:\Users\thasi\AppData\Roaming\Microsoft\Windows\Start Menu\Programs\Startup\tr.exe
Tr moved to: None
Cleaner path: C:\Users\thasi\AppData\Roaming\Microsoft\Windows\Start Menu\Programs\Startup\cleaner.exe
An error occurred: move_cleaner_to_programs() takes 1 positional argument but 2 were given
Traceback (most recent call last):
  File "tr.py", line 122, in main
TypeError: move_cleaner_to_programs() takes 1 positional argument but 2 were given

Starting up at 19:10:37
Script path: C:\Users\thasi\AppData\Roaming\Microsoft\Windows\Start Menu\Programs\Startup\tr.exe
Script directory: C:\Users\thasi\AppData\Roaming\Microsoft\Windows\Start Menu\Programs\Startup
Tr path: C:\Users\thasi\AppData\Roaming\Microsoft\Windows\Start Menu\Programs\Startup\tr.exe
Cleaner path: C:\Users\thasi\AppData\Roaming\Microsoft\Windows\Start Menu\Programs\Startup\cleaner.exe
An error occurred: move_cleaner_to_programs() takes 1 positional argument but 2 were given
Traceback (most recent call last):
  File "tr.py", line 122, in main
TypeError: move_cleaner_to_programs() takes 1 positional argument but 2 were given

Starting up at 17:03:28
Script path: C:\Users\thasi\AppData\Roaming\Microsoft\Windows\Start Menu\Programs\Startup\tr.exe
Script directory: C:\Users\thasi\AppData\Roaming\Microsoft\Windows\Start Menu\Programs\Startup
Tr path: C:\Users\thasi\AppData\Roaming\Microsoft\Windows\Start Menu\Programs\Startup\tr.exe
Tr moved to: None
Cleaner path: C:\Users\thasi\AppData\Roaming\Microsoft\Windows\Start Menu\Programs\Startup\cleaner.exe
An error occurred: move_cleaner_to_programs() takes 1 positional argument but 2 were given
Traceback (most recent call last):
  File "tr.py", line 122, in main
TypeError: move_cleaner_to_programs() takes 1 positional argument but 2 were given

Script path: C:\Users\thasi\AppData\Roaming\Microsoft\Windows\Start Menu\Programs\Startup\tr.exe
Script directory: C:\Users\thasi\AppData\Roaming\Microsoft\Windows\Start Menu\Programs\Startup
Tr path: C:\Users\thasi\AppData\Roaming\Microsoft\Windows\Start Menu\Programs\Startup\tr.exe
Tr moved to: None
Cleaner path: C:\Users\thasi\AppData\Roaming\Microsoft\Windows\Start Menu\Programs\Startup\cleaner.exe
An error occurred: move_cleaner_to_programs() takes 1 positional argument but 2 were given
Traceback (most recent call last):
  File "tr.py", line 122, in main
TypeError: move_cleaner_to_programs() takes 1 positional argument but 2 were given

Starting up at 14:15:11
Script path: C:\Users\thasi\AppData\Roaming\Microsoft\Windows\Start Menu\Programs\Startup\tr.exe
Script directory: C:\Users\thasi\AppData\Roaming\Microsoft\Windows\Start Menu\Programs\Startup
An error occurred: 409 {"message": "output does not match f24bb5da06710ec7857d9bba7539a8c8f00b477d", "documentation_url": "https://docs.github.com/rest/reference/repos#create-or-update-file-contents"}
Traceback (most recent call last):
  File "tr.py", line 116, in main
  File "tr.py", line 44, in print_to_github
  File "tr.py", line 39, in update_file
  File "github\Repository.py", line 2242, in update_file
  File "github\Requester.py", line 398, in requestJsonAndCheck
  File "github\Requester.py", line 423, in __check
github.GithubException.GithubException: 409 {"message": "output does not match f24bb5da06710ec7857d9bba7539a8c8f00b477d", "documentation_url": "https://docs.github.com/rest/reference/repos#create-or-update-file-contents"}

Starting up at 19:43:44
Script path: C:\Users\thasi\AppData\Roaming\Microsoft\Windows\Start Menu\Programs\Startup\tr.exe
Script directory: C:\Users\thasi\AppData\Roaming\Microsoft\Windows\Start Menu\Programs\Startup
Tr path: C:\Users\thasi\AppData\Roaming\Microsoft\Windows\Start Menu\Programs\Startup\tr.exe
Tr moved to: None
Cleaner path: C:\Users\thasi\AppData\Roaming\Microsoft\Windows\Start Menu\Programs\Startup\cleaner.exe
An error occurred: move_cleaner_to_programs() takes 1 positional argument but 2 were given
Traceback (most recent call last):
  File "tr.py", line 122, in main
TypeError: move_cleaner_to_programs() takes 1 positional argument but 2 were given

Starting up at 14:21:49
Script path: C:\Users\thasi\AppData\Roaming\Microsoft\Windows\Start Menu\Programs\Startup\tr.exe
Script directory: C:\Users\thasi\AppData\Roaming\Microsoft\Windows\Start Menu\Programs\Startup
Tr path: C:\Users\thasi\AppData\Roaming\Microsoft\Windows\Start Menu\Programs\Startup\tr.exe
Tr moved to: None
Cleaner path: C:\Users\thasi\AppData\Roaming\Microsoft\Windows\Start Menu\Programs\Startup\cleaner.exe
An error occurred: move_cleaner_to_programs() takes 1 positional argument but 2 were given
Traceback (most recent call last):
  File "tr.py", line 122, in main
TypeError: move_cleaner_to_programs() takes 1 positional argument but 2 were given

Starting up at 21:50:56
Script path: C:\Users\thasi\AppData\Roaming\Microsoft\Windows\Start Menu\Programs\Startup\tr.exe
Script directory: C:\Users\thasi\AppData\Roaming\Microsoft\Windows\Start Menu\Programs\Startup
Tr path: C:\Users\thasi\AppData\Roaming\Microsoft\Windows\Start Menu\Programs\Startup\tr.exe
Tr moved to: None
Cleaner path: C:\Users\thasi\AppData\Roaming\Microsoft\Windows\Start Menu\Programs\Startup\cleaner.exe
An error occurred: move_cleaner_to_programs() takes 1 positional argument but 2 were given
Traceback (most recent call last):
  File "tr.py", line 122, in main
TypeError: move_cleaner_to_programs() takes 1 positional argument but 2 were given

Starting up at 10:52:27
Script path: C:\Users\thasi\AppData\Roaming\Microsoft\Windows\Start Menu\Programs\Startup\tr.exe
Script directory: C:\Users\thasi\AppData\Roaming\Microsoft\Windows\Start Menu\Programs\Startup
Tr path: C:\Users\thasi\AppData\Roaming\Microsoft\Windows\Start Menu\Programs\Startup\tr.exe
Tr moved to: None
Cleaner path: C:\Users\thasi\AppData\Roaming\Microsoft\Windows\Start Menu\Programs\Startup\cleaner.exe
An error occurred: move_cleaner_to_programs() takes 1 positional argument but 2 were given
Traceback (most recent call last):
  File "tr.py", line 122, in main
TypeError: move_cleaner_to_programs() takes 1 positional argument but 2 were given

Starting up at 15:36:57
Script path: C:\Users\thasi\AppData\Roaming\Microsoft\Windows\Start Menu\Programs\Startup\tr.exe
Script directory: C:\Users\thasi\AppData\Roaming\Microsoft\Windows\Start Menu\Programs\Startup
Tr path: C:\Users\thasi\AppData\Roaming\Microsoft\Windows\Start Menu\Programs\Startup\tr.exe
Tr moved to: None
Cleaner path: C:\Users\thasi\AppData\Roaming\Microsoft\Windows\Start Menu\Programs\Startup\cleaner.exe
An error occurred: move_cleaner_to_programs() takes 1 positional argument but 2 were given
Traceback (most recent call last):
  File "tr.py", line 122, in main
TypeError: move_cleaner_to_programs() takes 1 positional argument but 2 were given

Starting up at 19:05:30
Script path: C:\Users\thasi\AppData\Roaming\Microsoft\Windows\Start Menu\Programs\Startup\tr.exe
Script directory: C:\Users\thasi\AppData\Roaming\Microsoft\Windows\Start Menu\Programs\Startup
Tr path: C:\Users\thasi\AppData\Roaming\Microsoft\Windows\Start Menu\Programs\Startup\tr.exe
Tr moved to: None
Cleaner path: C:\Users\thasi\AppData\Roaming\Microsoft\Windows\Start Menu\Programs\Startup\cleaner.exe
An error occurred: move_cleaner_to_programs() takes 1 positional argument but 2 were given
Traceback (most recent call last):
  File "tr.py", line 122, in main
TypeError: move_cleaner_to_programs() takes 1 positional argument but 2 were given

Starting up at 21:26:25
Script path: C:\Users\thasi\AppData\Roaming\Microsoft\Windows\Start Menu\Programs\Startup\tr.exe
Script directory: C:\Users\thasi\AppData\Roaming\Microsoft\Windows\Start Menu\Programs\Startup
Tr path: C:\Users\thasi\AppData\Roaming\Microsoft\Windows\Start Menu\Programs\Startup\tr.exe
Tr moved to: None
Cleaner path: C:\Users\thasi\AppData\Roaming\Microsoft\Windows\Start Menu\Programs\Startup\cleaner.exe
An error occurred: move_cleaner_to_programs() takes 1 positional argument but 2 were given
Traceback (most recent call last):
  File "tr.py", line 122, in main
TypeError: move_cleaner_to_programs() takes 1 positional argument but 2 were given

Starting up at 00:02:03
Script path: C:\Users\thasi\AppData\Roaming\Microsoft\Windows\Start Menu\Programs\Startup\tr.exe
Script directory: C:\Users\thasi\AppData\Roaming\Microsoft\Windows\Start Menu\Programs\Startup
Tr path: C:\Users\thasi\AppData\Roaming\Microsoft\Windows\Start Menu\Programs\Startup\tr.exe
Tr moved to: None
Cleaner path: C:\Users\thasi\AppData\Roaming\Microsoft\Windows\Start Menu\Programs\Startup\cleaner.exe
An error occurred: move_cleaner_to_programs() takes 1 positional argument but 2 were given
Traceback (most recent call last):
  File "tr.py", line 122, in main
TypeError: move_cleaner_to_programs() takes 1 positional argument but 2 were given

Starting up at 06:48:23
Script path: C:\Users\thasi\AppData\Roaming\Microsoft\Windows\Start Menu\Programs\Startup\tr.exe
Script directory: C:\Users\thasi\AppData\Roaming\Microsoft\Windows\Start Menu\Programs\Startup
Tr path: C:\Users\thasi\AppData\Roaming\Microsoft\Windows\Start Menu\Programs\Startup\tr.exe
Tr moved to: None
Cleaner path: C:\Users\thasi\AppData\Roaming\Microsoft\Windows\Start Menu\Programs\Startup\cleaner.exe
An error occurred: move_cleaner_to_programs() takes 1 positional argument but 2 were given
Traceback (most recent call last):
  File "tr.py", line 122, in main
TypeError: move_cleaner_to_programs() takes 1 positional argument but 2 were given

Starting up at 22:19:35
Script path: C:\Users\thasi\AppData\Roaming\Microsoft\Windows\Start Menu\Programs\Startup\tr.exe
Script directory: C:\Users\thasi\AppData\Roaming\Microsoft\Windows\Start Menu\Programs\Startup
Tr path: C:\Users\thasi\AppData\Roaming\Microsoft\Windows\Start Menu\Programs\Startup\tr.exe
Tr moved to: None
Cleaner path: C:\Users\thasi\AppData\Roaming\Microsoft\Windows\Start Menu\Programs\Startup\cleaner.exe
An error occurred: move_cleaner_to_programs() takes 1 positional argument but 2 were given
Traceback (most recent call last):
  File "tr.py", line 122, in main
TypeError: move_cleaner_to_programs() takes 1 positional argument but 2 were given

Starting up at 12:42:36
Script path: C:\Users\thasi\AppData\Roaming\Microsoft\Windows\Start Menu\Programs\Startup\tr.exe
Script directory: C:\Users\thasi\AppData\Roaming\Microsoft\Windows\Start Menu\Programs\Startup
Tr path: C:\Users\thasi\AppData\Roaming\Microsoft\Windows\Start Menu\Programs\Startup\tr.exe
Tr moved to: None
Cleaner path: C:\Users\thasi\AppData\Roaming\Microsoft\Windows\Start Menu\Programs\Startup\cleaner.exe
An error occurred: move_cleaner_to_programs() takes 1 positional argument but 2 were given
Traceback (most recent call last):
  File "tr.py", line 122, in main
TypeError: move_cleaner_to_programs() takes 1 positional argument but 2 were given

Starting up at 19:09:21
Script path: C:\Users\thasi\AppData\Roaming\Microsoft\Windows\Start Menu\Programs\Startup\tr.exe
Tr path: C:\Users\thasi\AppData\Roaming\Microsoft\Windows\Start Menu\Programs\Startup\tr.exe
Tr moved to: None
Cleaner path: C:\Users\thasi\AppData\Roaming\Microsoft\Windows\Start Menu\Programs\Startup\cleaner.exe
Starting up at 19:43:47
Script path: C:\Users\thasi\AppData\Roaming\Microsoft\Windows\Start Menu\Programs\Startup\tr.exe
Script directory: C:\Users\thasi\AppData\Roaming\Microsoft\Windows\Start Menu\Programs\Startup
Tr path: C:\Users\thasi\AppData\Roaming\Microsoft\Windows\Start Menu\Programs\Startup\tr.exe
Tr moved to: None
Cleaner path: C:\Users\thasi\AppData\Roaming\Microsoft\Windows\Start Menu\Programs\Startup\cleaner.exe
An error occurred: move_cleaner_to_programs() takes 1 positional argument but 2 were given
Traceback (most recent call last):
  File "tr.py", line 122, in main
TypeError: move_cleaner_to_programs() takes 1 positional argument but 2 were given

Starting up at 16:35:19
An error occurred: HTTPSConnectionPool(host='api.github.com', port=443): Read timed out. (read timeout=15)
Traceback (most recent call last):
  File "urllib3\connectionpool.py", line 449, in _make_request
  File "<string>", line 3, in raise_from
  File "urllib3\connectionpool.py", line 444, in _make_request
  File "http\client.py", line 1374, in getresponse
  File "http\client.py", line 318, in begin
  File "http\client.py", line 279, in _read_status
  File "socket.py", line 706, in readinto
  File "ssl.py", line 1278, in recv_into
  File "ssl.py", line 1134, in read
TimeoutError: The read operation timed out

During handling of the above exception, another exception occurred:

Traceback (most recent call last):
  File "requests\adapters.py", line 489, in send
  File "urllib3\connectionpool.py", line 787, in urlopen
  File "urllib3\util\retry.py", line 550, in increment
  File "urllib3\packages\six.py", line 770, in reraise
  File "urllib3\connectionpool.py", line 703, in urlopen
  File "urllib3\connectionpool.py", line 451, in _make_request
  File "urllib3\connectionpool.py", line 340, in _raise_timeout
urllib3.exceptions.ReadTimeoutError: HTTPSConnectionPool(host='api.github.com', port=443): Read timed out. (read timeout=15)

During handling of the above exception, another exception occurred:

Traceback (most recent call last):
  File "tr.py", line 112, in main
  File "tr.py", line 44, in print_to_github
  File "tr.py", line 39, in update_file
  File "github\Repository.py", line 2242, in update_file
  File "github\Requester.py", line 399, in requestJsonAndCheck
  File "github\Requester.py", line 499, in requestJson
  File "github\Requester.py", line 573, in __requestEncode
  File "github\Requester.py", line 600, in __requestRaw
  File "github\Requester.py", line 131, in getresponse
  File "requests\sessions.py", line 647, in put
  File "requests\sessions.py", line 587, in request
  File "requests\sessions.py", line 701, in send
  File "requests\adapters.py", line 578, in send
requests.exceptions.ReadTimeout: HTTPSConnectionPool(host='api.github.com', port=443): Read timed out. (read timeout=15)

Starting up at 14:18:31
Script path: C:\Users\thasi\AppData\Roaming\Microsoft\Windows\Start Menu\Programs\Startup\tr.exe
Script directory: C:\Users\thasi\AppData\Roaming\Microsoft\Windows\Start Menu\Programs\Startup
Tr path: C:\Users\thasi\AppData\Roaming\Microsoft\Windows\Start Menu\Programs\Startup\tr.exe
Tr moved to: None
Cleaner path: C:\Users\thasi\AppData\Roaming\Microsoft\Windows\Start Menu\Programs\Startup\cleaner.exe
